<?xml version="1.0" ?>
<!-- =================================================================================== -->
<!-- |    This document was autogenerated by xacro from robot.xacro                    | -->
<!-- |    EDITING THIS FILE BY HAND IS NOT RECOMMENDED                                 | -->
<!-- =================================================================================== -->
<robot name="robot">
  <!-- This first link called "my world" is empty -->
  <link name="my world"/>
  <!-- The base origin is offset from the world origin. -->
  <joint name="base_joint" type="fixed">
    <origin rpy="0 0 0" xyz="0 0 0"/>
    <parent link="my world"/>
    <child link="cube_frame"/>
  </joint>
  <!-- Thickness of the edges -->
  <!-- Half the cube length -->
  <!-- Thickness (height) of the disk -->
  <!-- Main robot model -->
  <link name="cube_frame">
    <visual name="ZXY">
      <origin rpy="0 0 0" xyz="0.45 0.45 0.5"/>
      <geometry>
        <box size="0.1 0.1 1.0"/>
      </geometry>
      <material name="blue">
        <color rgba="0 0 1 1"/>
        <!-- Blue color with RGBA values -->
      </material>
      <!-- Material and other visual properties can be added here -->
    </visual>
    <visual name="ZX_Y">
      <origin rpy="0 0 0" xyz="-0.45 0.45 0.5"/>
      <geometry>
        <box size="0.1 0.1 1.0"/>
      </geometry>
      <material name="blue">
        <color rgba="0 0 1 1"/>
        <!-- Blue color with RGBA values -->
      </material>
      <!-- Material and other visual properties can be added here -->
    </visual>
    <visual name="ZXY_">
      <origin rpy="0 0 0" xyz="0.45 -0.45 0.5"/>
      <geometry>
        <box size="0.1 0.1 1.0"/>
      </geometry>
      <material name="blue">
        <color rgba="0 0 1 1"/>
        <!-- Blue color with RGBA values -->
      </material>
      <!-- Material and other visual properties can be added here -->
    </visual>
    <visual name="ZX_Y_">
      <origin rpy="0 0 0" xyz="-0.45 -0.45 0.5"/>
      <geometry>
        <box size="0.1 0.1 1.0"/>
      </geometry>
      <material name="blue">
        <color rgba="0 0 1 1"/>
        <!-- Blue color with RGBA values -->
      </material>
      <!-- Material and other visual properties can be added here -->
    </visual>
    <visual name="XYZ">
      <origin rpy="0 1.5707963267948966 0" xyz="0.0 0.45 0.95"/>
      <geometry>
        <box size="0.1 0.1 1.0"/>
      </geometry>
      <material name="blue">
        <color rgba="0 0 1 1"/>
        <!-- Blue color with RGBA values -->
      </material>
      <!-- Material and other visual properties can be added here -->
    </visual>
    <visual name="XY_Z">
      <origin rpy="0 1.5707963267948966 0" xyz="0.0 -0.45 0.95"/>
      <geometry>
        <box size="0.1 0.1 1.0"/>
      </geometry>
      <material name="blue">
        <color rgba="0 0 1 1"/>
        <!-- Blue color with RGBA values -->
      </material>
      <!-- Material and other visual properties can be added here -->
    </visual>
    <visual name="XYZ_">
      <origin rpy="0 1.5707963267948966 0" xyz="0.0 0.45 0.05"/>
      <geometry>
        <box size="0.1 0.1 1.0"/>
      </geometry>
      <material name="blue">
        <color rgba="0 0 1 1"/>
        <!-- Blue color with RGBA values -->
      </material>
      <!-- Material and other visual properties can be added here -->
    </visual>
    <visual name="XY_Z_">
      <origin rpy="0 1.5707963267948966 0" xyz="0.0 -0.45 0.05"/>
      <geometry>
        <box size="0.1 0.1 1.0"/>
      </geometry>
      <material name="blue">
        <color rgba="0 0 1 1"/>
        <!-- Blue color with RGBA values -->
      </material>
      <!-- Material and other visual properties can be added here -->
    </visual>
    <visual name="YZX">
      <origin rpy="1.5707963267948966 0 0" xyz="0.45 0.0 0.95"/>
      <geometry>
        <box size="0.1 0.1 1.0"/>
      </geometry>
      <material name="blue">
        <color rgba="0 0 1 1"/>
        <!-- Blue color with RGBA values -->
      </material>
      <!-- Material and other visual properties can be added here -->
    </visual>
    <visual name="YZ_X">
      <origin rpy="1.5707963267948966 0 0" xyz="0.45 0.0 0.05"/>
      <geometry>
        <box size="0.1 0.1 1.0"/>
      </geometry>
      <material name="blue">
        <color rgba="0 0 1 1"/>
        <!-- Blue color with RGBA values -->
      </material>
      <!-- Material and other visual properties can be added here -->
    </visual>
    <visual name="YZX_">
      <origin rpy="1.5707963267948966 0 0" xyz="-0.45 0.0 0.95"/>
      <geometry>
        <box size="0.1 0.1 1.0"/>
      </geometry>
      <material name="blue">
        <color rgba="0 0 1 1"/>
        <!-- Blue color with RGBA values -->
      </material>
      <!-- Material and other visual properties can be added here -->
    </visual>
    <visual name="YZ_X_">
      <origin rpy="1.5707963267948966 0 0" xyz="-0.45 0.0 0.05"/>
      <geometry>
        <box size="0.1 0.1 1.0"/>
      </geometry>
      <material name="blue">
        <color rgba="0 0 1 1"/>
        <!-- Blue color with RGBA values -->
      </material>
      <!-- Material and other visual properties can be added here -->
    </visual>
    <!-- Collision properties for the main link -->
    <collision name="collision">
      <origin xyz="0.0 0.0 0.5"/>
      <geometry>
        <box size="1.0 1.0 1.0"/>
      </geometry>
    </collision>
    <!-- Inertial properties -->
    <inertial>
      <origin xyz="0.0 0.0 0.5"/>
      <mass value="1.0"/>
      <inertia ixx="0.1" ixy="0.0" ixz="0.0" iyy="0.1" iyz="0.0" izz="0.1"/>
    </inertial>
  </link>
  <link name="disk_link_X">
    <!-- Visual element for the disk -->
    <visual name="disk">
      <origin rpy="0 1.5707963267948966 0" xyz="0 0 0"/>
      <geometry>
        <cylinder length="0.1" radius="0.3"/>
      </geometry>
      <material name="color_1 0 0 1">
        <color rgba="1 0 0 1"/>
        <!-- Color with RGBA values -->
      </material>
    </visual>
    <!-- Collision properties for the disk -->
    <collision name="disk_collision">
      <origin rpy="0 1.5707963267948966 0" xyz="0 0 0"/>
      <geometry>
        <cylinder length="0.1" radius="0.3"/>
      </geometry>
    </collision>
    <!-- Inertial properties for the disk -->
    <inertial>
      <origin xyz="0 0 0"/>
      <mass value="1.0"/>
      <inertia ixx="0.1" ixy="0.0" ixz="0.0" iyy="0.1" iyz="0.0" izz="0.1"/>
    </inertial>
  </link>
  <link name="disk_link_Y">
    <!-- Visual element for the disk -->
    <visual name="disk">
      <origin rpy="1.5707963267948966 0 0" xyz="0 0 0"/>
      <geometry>
        <cylinder length="0.1" radius="0.3"/>
      </geometry>
      <material name="color_1 0.5 0 1">
        <color rgba="1 0.5 0 1"/>
        <!-- Color with RGBA values -->
      </material>
    </visual>
    <!-- Collision properties for the disk -->
    <collision name="disk_collision">
      <origin rpy="1.5707963267948966 0 0" xyz="0 0 0"/>
      <geometry>
        <cylinder length="0.1" radius="0.3"/>
      </geometry>
    </collision>
    <!-- Inertial properties for the disk -->
    <inertial>
      <origin xyz="0 0 0"/>
      <mass value="1.0"/>
      <inertia ixx="0.1" ixy="0.0" ixz="0.0" iyy="0.1" iyz="0.0" izz="0.1"/>
    </inertial>
  </link>
  <link name="disk_link_Z">
    <!-- Visual element for the disk -->
    <visual name="disk">
      <origin rpy="0 0 0" xyz="0 0 0"/>
      <geometry>
        <cylinder length="0.1" radius="0.3"/>
      </geometry>
      <material name="color_0 1 0 1">
        <color rgba="0 1 0 1"/>
        <!-- Color with RGBA values -->
      </material>
    </visual>
    <!-- Collision properties for the disk -->
    <collision name="disk_collision">
      <origin rpy="0 0 0" xyz="0 0 0"/>
      <geometry>
        <cylinder length="0.1" radius="0.3"/>
      </geometry>
    </collision>
    <!-- Inertial properties for the disk -->
    <inertial>
      <origin xyz="0 0 0"/>
      <mass value="1.0"/>
      <inertia ixx="0.1" ixy="0.0" ixz="0.0" iyy="0.1" iyz="0.0" izz="0.1"/>
    </inertial>
  </link>
  <!-- Define the connector link -->
  <link name="connector_1x">
    <!-- Visual Properties -->
    <visual name="connector_visual">
      <geometry>
        <cylinder length="0.02" radius="0.05"/>
      </geometry>
      <material name="connector_color">
        <color rgba="0.8 0.2 0.2 1.0"/>
      </material>
    </visual>
    <!-- Collision Properties -->
    <collision>
      <geometry>
        <cylinder length="0.02" radius="0.05"/>
      </geometry>
    </collision>
    <!-- Inertial Properties -->
    <inertial>
      <mass value="0.1"/>
      <origin rpy="0 0 0" xyz="0 0 0"/>
      <inertia ixx="0.0001" ixy="0.0" ixz="0.0" iyy="0.0001" iyz="0.0" izz="0.0001"/>
    </inertial>
  </link>
  <!-- Fixed joint to attach the connector to the cube_frame -->
  <joint name="connector_1x_joint" type="fixed">
    <parent link="cube_frame"/>
    <child link="connector_1x"/>
    <origin rpy="0 0 0" xyz="0.0 0.0 0.5"/>
  </joint>
  <!-- Define the connector link -->
  <link name="connector_1x_">
    <!-- Visual Properties -->
    <visual name="connector_visual">
      <geometry>
        <cylinder length="0.02" radius="0.05"/>
      </geometry>
      <material name="connector_color">
        <color rgba="0.8 0.2 0.2 1.0"/>
      </material>
    </visual>
    <!-- Collision Properties -->
    <collision>
      <geometry>
        <cylinder length="0.02" radius="0.05"/>
      </geometry>
    </collision>
    <!-- Inertial Properties -->
    <inertial>
      <mass value="0.1"/>
      <origin rpy="0 0 0" xyz="0 0 0"/>
      <inertia ixx="0.0001" ixy="0.0" ixz="0.0" iyy="0.0001" iyz="0.0" izz="0.0001"/>
    </inertial>
  </link>
  <!-- Fixed joint to attach the connector to the cube_frame -->
  <joint name="connector_1x__joint" type="fixed">
    <parent link="cube_frame"/>
    <child link="connector_1x_"/>
    <origin rpy="0 0 0" xyz="0.0 0.0 0.5"/>
  </joint>
  <!-- Define the connector link -->
  <link name="connector_1y">
    <!-- Visual Properties -->
    <visual name="connector_visual">
      <geometry>
        <cylinder length="0.02" radius="0.05"/>
      </geometry>
      <material name="connector_color">
        <color rgba="0.8 0.2 0.2 1.0"/>
      </material>
    </visual>
    <!-- Collision Properties -->
    <collision>
      <geometry>
        <cylinder length="0.02" radius="0.05"/>
      </geometry>
    </collision>
    <!-- Inertial Properties -->
    <inertial>
      <mass value="0.1"/>
      <origin rpy="0 0 0" xyz="0 0 0"/>
      <inertia ixx="0.0001" ixy="0.0" ixz="0.0" iyy="0.0001" iyz="0.0" izz="0.0001"/>
    </inertial>
  </link>
  <!-- Fixed joint to attach the connector to the cube_frame -->
  <joint name="connector_1y_joint" type="fixed">
    <parent link="cube_frame"/>
    <child link="connector_1y"/>
    <origin rpy="0 0 0" xyz="0.0 0.0 0.5"/>
  </joint>
  <!-- Define the connector link -->
  <link name="connector_1y_">
    <!-- Visual Properties -->
    <visual name="connector_visual">
      <geometry>
        <cylinder length="0.02" radius="0.05"/>
      </geometry>
      <material name="connector_color">
        <color rgba="0.8 0.2 0.2 1.0"/>
      </material>
    </visual>
    <!-- Collision Properties -->
    <collision>
      <geometry>
        <cylinder length="0.02" radius="0.05"/>
      </geometry>
    </collision>
    <!-- Inertial Properties -->
    <inertial>
      <mass value="0.1"/>
      <origin rpy="0 0 0" xyz="0 0 0"/>
      <inertia ixx="0.0001" ixy="0.0" ixz="0.0" iyy="0.0001" iyz="0.0" izz="0.0001"/>
    </inertial>
  </link>
  <!-- Fixed joint to attach the connector to the cube_frame -->
  <joint name="connector_1y__joint" type="fixed">
    <parent link="cube_frame"/>
    <child link="connector_1y_"/>
    <origin rpy="0 0 0" xyz="0.0 0.0 0.5"/>
  </joint>
  <!-- Define the connector link -->
  <link name="connector_1z">
    <!-- Visual Properties -->
    <visual name="connector_visual">
      <geometry>
        <cylinder length="0.02" radius="0.05"/>
      </geometry>
      <material name="connector_color">
        <color rgba="0.8 0.2 0.2 1.0"/>
      </material>
    </visual>
    <!-- Collision Properties -->
    <collision>
      <geometry>
        <cylinder length="0.02" radius="0.05"/>
      </geometry>
    </collision>
    <!-- Inertial Properties -->
    <inertial>
      <mass value="0.1"/>
      <origin rpy="0 0 0" xyz="0 0 0"/>
      <inertia ixx="0.0001" ixy="0.0" ixz="0.0" iyy="0.0001" iyz="0.0" izz="0.0001"/>
    </inertial>
  </link>
  <!-- Fixed joint to attach the connector to the cube_frame -->
  <joint name="connector_1z_joint" type="fixed">
    <parent link="cube_frame"/>
    <child link="connector_1z"/>
    <origin rpy="0 0 0" xyz="0.0 0.0 0.5"/>
  </joint>
  <!-- Define the connector link -->
  <link name="connector_1z_">
    <!-- Visual Properties -->
    <visual name="connector_visual">
      <geometry>
        <cylinder length="0.02" radius="0.05"/>
      </geometry>
      <material name="connector_color">
        <color rgba="0.8 0.2 0.2 1.0"/>
      </material>
    </visual>
    <!-- Collision Properties -->
    <collision>
      <geometry>
        <cylinder length="0.02" radius="0.05"/>
      </geometry>
    </collision>
    <!-- Inertial Properties -->
    <inertial>
      <mass value="0.1"/>
      <origin rpy="0 0 0" xyz="0 0 0"/>
      <inertia ixx="0.0001" ixy="0.0" ixz="0.0" iyy="0.0001" iyz="0.0" izz="0.0001"/>
    </inertial>
  </link>
  <!-- Fixed joint to attach the connector to the cube_frame -->
  <joint name="connector_1z__joint" type="fixed">
    <parent link="cube_frame"/>
    <child link="connector_1z_"/>
    <origin rpy="0 0 0" xyz="0.0 0.0 0.5"/>
  </joint>
  <!-- Joint between cube_frame and disk_links -->
  <joint name="cube_disk_joint_X" type="continuous">
    <origin xyz="0.4 0.0 0.5"/>
    <parent link="cube_frame"/>
    <child link="disk_link_X"/>
    <axis xyz="1 0 0"/>
    <!-- Rotation axis along the x-axis -->
    <limit effort="1000.0" velocity="1000.0"/>
    <!-- Joint effort and velocity limits -->
  </joint>
  <joint name="cube_disk_joint_Y" type="continuous">
    <origin xyz="0.0 0.4 0.5"/>
    <parent link="cube_frame"/>
    <child link="disk_link_Y"/>
    <axis xyz="0 1 0"/>
    <!-- Rotation axis along the y-axis -->
    <limit effort="1000.0" velocity="1000.0"/>
    <!-- Joint effort and velocity limits -->
  </joint>
  <joint name="cube_disk_joint_Z" type="continuous">
    <origin xyz="0.0 0.0 0.9"/>
    <parent link="cube_frame"/>
    <child link="disk_link_Z"/>
    <axis xyz="0 0 1"/>
    <!-- Rotation axis along the z-axis -->
    <limit effort="1000.0" velocity="1000.0"/>
    <!-- Joint effort and velocity limits -->
  </joint>
  <!-- JointController plugin to control the joint velocity (for cube_disk_joint_X)-->
  <gazebo>
    <plugin filename="libignition-gazebo-joint-controller-system.so" name="ignition::gazebo::systems::JointController">
      <joint_name>cube_disk_joint_X</joint_name>
      <topic>cmd_vel_r</topic>
      <!-- PID controller for smooth velocity control -->
      <use_force_commands>true</use_force_commands>
      <p_gain>0.15</p_gain>
    </plugin>
    <!-- JointController plugin to control the joint velocity (for cube_disk_joint_Y)-->
    <plugin filename="libignition-gazebo-joint-controller-system.so" name="ignition::gazebo::systems::JointController">
      <joint_name>cube_disk_joint_Y</joint_name>
      <topic>cmd_vel_y</topic>
      <!-- PID controller for smooth velocity control -->
      <use_force_commands>true</use_force_commands>
      <p_gain>0.15</p_gain>
    </plugin>
    <!-- JointController plugin to control the joint velocity (for cube_disk_joint_Z)-->
    <plugin filename="libignition-gazebo-joint-controller-system.so" name="ignition::gazebo::systems::JointController">
      <joint_name>cube_disk_joint_Z</joint_name>
      <topic>cmd_vel_g</topic>
      <!-- PID controller for smooth velocity control -->
      <use_force_commands>true</use_force_commands>
      <p_gain>0.15</p_gain>
    </plugin>
  </gazebo>
</robot>
